Workbook

Sheet summary
A1: summary | F1: Current Date | G1: =MAX(actuals!F:F) -> 46249
C3: =SUM(C5:C17) -> 955 | D3: =SUM(D5:D17) -> 50000 | E3: =SUM(E5:E17) -> 43276.5 | F3: =SUM(F5:F17) -> 421 | G3: =SUM(G5:G17) -> 26067 | H3: =SUM(H5:H17) -> 23460.3 | I3: =SUM(I5:I17) -> 515 | J3: =SUM(J5:J17) -> 21525 | ... Q3: =SUM(Q5:Q17) -> -443.7
A4: Task Code | B4: Task Name | C4: Benchmark Hours | D4: Benchmark Bill | E4: Benchmark FBLR | F4: Actuals To Date Hours | G4: Actuals To Date Bill | H4: Actuals To Date FBLR | I4: Estimate to Complete Hours | J4: Estimate to Complete Bill | K4: Estimate to Complete FBLR | L4: Estimate at Completion Hours | M4: Estimate at Completion Bill | N4: Estimate at Completion FBLR | O4: Variance Hours | P4: Variance Bill | Q4: Variance FBLR
A5: T-101 | B5: Requirements gathering | C5: =SUMIFS('fact forecasts'!$I:$I,'fact forecasts'!$A:$A,summary!$A5) -> 30 | D5: =SUMIFS('fact forecasts'!$L:$L,'fact forecasts'!$A:$A,summary!$A5) -> 3000 | E5: =SUMIFS('fact forecasts'!$M:$M,'fact forecasts'!$A:$A,summary!$A5) -> 2700 | F5: =SUMIFS(actuals!$G:$G,actuals!$A:$A,summary!$A5) -> 28 | G5: =SUMIFS(actuals!$J:$J,actuals!$A:$A,summary!$A5) -> 2800 | H5: =SUMIFS(actuals!$K:$K,actuals!$A:$A,summary!$A5) -> 2520 | I5: =SUMIFS('fact forecasts'!$I:$I,'fact forecasts'!$A:$A,summary!$A5,'fact forecasts'!$G:$G,">"&summary!$G$1) -> 0 | J5: =SUMIFS('fact forecasts'!$L:$L,'fact forecasts'!$A:$A,summary!$A5,'fact forecasts'!$G:$G,">"&summary!$G$1) -> 0 | K5: =SUMIFS('fact forecasts'!$M:$M,'fact forecasts'!$A:$A,summary!$A5,'fact forecasts'!$G:$G,">"&summary!$G$1) -> 0 | L5: =F5+I5 -> 28 | M5: =G5+J5 -> 2800 | N5: =H5+K5 -> 2520 | O5: =L5-C5 -> -2 | P5: =M5-D5 -> -200 | Q5: =N5-E5 -> -180
A6: T-102 | B6: Scope definition | C6: =SUMIFS('fact forecasts'!$I:$I,'fact forecasts'!$A:$A,summary!$A6) -> 30 | D6: =SUMIFS('fact forecasts'!$L:$L,'fact forecasts'!$A:$A,summary!$A6) -> 2600 | E6: =SUMIFS('fact forecasts'!$M:$M,'fact forecasts'!$A:$A,summary!$A6) -> 2340 | F6: =SUMIFS(actuals!$G:$G,actuals!$A:$A,summary!$A6) -> 34 | G6: =SUMIFS(actuals!$J:$J,actuals!$A:$A,summary!$A6) -> 2980 | H6: =SUMIFS(actuals!$K:$K,actuals!$A:$A,summary!$A6) -> 2682 | I6: =SUMIFS('fact forecasts'!$I:$I,'fact forecasts'!$A:$A,summary!$A6,'fact forecasts'!$G:$G,">"&summary!$G$1) -> 0 | J6: =SUMIFS('fact forecasts'!$L:$L,'fact forecasts'!$A:$A,summary!$A6,'fact forecasts'!$G:$G,">"&summary!$G$1) -> 0 | K6: =SUMIFS('fact forecasts'!$M:$M,'fact forecasts'!$A:$A,summary!$A6,'fact forecasts'!$G:$G,">"&summary!$G$1) -> 0 | L6: =F6+I6 -> 34 | M6: =G6+J6 -> 2980 | N6: =H6+K6 -> 2682 | O6: =L6-C6 -> 4 | P6: =M6-D6 -> 380 | Q6: =N6-E6 -> 342
A7: T-103 | B7: Project planning | C7: =SUMIFS('fact forecasts'!$I:$I,'fact forecasts'!$A:$A,summary!$A7) -> 60 | D7: =SUMIFS('fact forecasts'!$L:$L,'fact forecasts'!$A:$A,summary!$A7) -> 5200 | E7: =SUMIFS('fact forecasts'!$M:$M,'fact forecasts'!$A:$A,summary!$A7) -> 4680 | F7: =SUMIFS(actuals!$G:$G,actuals!$A:$A,summary!$A7) -> 55 | G7: =SUMIFS(actuals!$J:$J,actuals!$A:$A,summary!$A7) -> 4800 | H7: =SUMIFS(actuals!$K:$K,actuals!$A:$A,summary!$A7) -> 4320 | I7: =SUMIFS('fact forecasts'!$I:$I,'fact forecasts'!$A:$A,summary!$A7,'fact forecasts'!$G:$G,">"&summary!$G$1) -> 0 | J7: =SUMIFS('fact forecasts'!$L:$L,'fact forecasts'!$A:$A,summary!$A7,'fact forecasts'!$G:$G,">"&summary!$G$1) -> 0 | K7: =SUMIFS('fact forecasts'!$M:$M,'fact forecasts'!$A:$A,summary!$A7,'fact forecasts'!$G:$G,">"&summary!$G$1) -> 0 | L7: =F7+I7 -> 55 | M7: =G7+J7 -> 4800 | N7: =H7+K7 -> 4320 | O7: =L7-C7 -> -5 | P7: =M7-D7 -> -400 | Q7: =N7-E7 -> -360
A8: T-104 | B8: Solution design | C8: =SUMIFS('fact forecasts'!$I:$I,'fact forecasts'!$A:$A,summary!$A8) -> 60 | D8: =SUMIFS('fact forecasts'!$L:$L,'fact forecasts'!$A:$A,summary!$A8) -> 4100 | E8: =SUMIFS('fact forecasts'!$M:$M,'fact forecasts'!$A:$A,summary!$A8) -> 3690 | F8: =SUMIFS(actuals!$G:$G,actuals!$A:$A,summary!$A8) -> 55 | G8: =SUMIFS(actuals!$J:$J,actuals!$A:$A,summary!$A8) -> 3785 | H8: =SUMIFS(actuals!$K:$K,actuals!$A:$A,summary!$A8) -> 3406.5 | I8: =SUMIFS('fact forecasts'!$I:$I,'fact forecasts'!$A:$A,summary!$A8,'fact forecasts'!$G:$G,">"&summary!$G$1) -> 0 | J8: =SUMIFS('fact forecasts'!$L:$L,'fact forecasts'!$A:$A,summary!$A8,'fact forecasts'!$G:$G,">"&summary!$G$1) -> 0 | K8: =SUMIFS('fact forecasts'!$M:$M,'fact forecasts'!$A:$A,summary!$A8,'fact forecasts'!$G:$G,">"&summary!$G$1) -> 0 | L8: =F8+I8 -> 55 | M8: =G8+J8 -> 3785 | N8: =H8+K8 -> 3406.5 | O8: =L8-C8 -> -5 | P8: =M8-D8 -> -315 | Q8: =N8-E8 -> -283.5
A9: T-105 | B9: Database design | C9: =SUMIFS('fact forecasts'!$I:$I,'fact forecasts'!$A:$A,summary!$A9) -> 60 | D9: =SUMIFS('fact forecasts'!$L:$L,'fact forecasts'!$A:$A,summary!$A9) -> 4100 | E9: =SUMIFS('fact forecasts'!$M:$M,'fact forecasts'!$A:$A,summary!$A9) -> 3690 | F9: =SUMIFS(actuals!$G:$G,actuals!$A:$A,summary!$A9) -> 60 | G9: =SUMIFS(actuals!$J:$J,actuals!$A:$A,summary!$A9) -> 4163 | H9: =SUMIFS(actuals!$K:$K,actuals!$A:$A,summary!$A9) -> 3746.7 | I9: =SUMIFS('fact forecasts'!$I:$I,'fact forecasts'!$A:$A,summary!$A9,'fact forecasts'!$G:$G,">"&summary!$G$1) -> 0 | J9: =SUMIFS('fact forecasts'!$L:$L,'fact forecasts'!$A:$A,summary!$A9,'fact forecasts'!$G:$G,">"&summary!$G$1) -> 0 | K9: =SUMIFS('fact forecasts'!$M:$M,'fact forecasts'!$A:$A,summary!$A9,'fact forecasts'!$G:$G,">"&summary!$G$1) -> 0 | L9: =F9+I9 -> 60 | M9: =G9+J9 -> 4163 | N9: =H9+K9 -> 3746.7 | O9: =L9-C9 -> 0 | P9: =M9-D9 -> 63 | Q9: =N9-E9 -> 56.7
A10: T-106 | B10: Front-end development | C10: =SUMIFS('fact forecasts'!$I:$I,'fact forecasts'!$A:$A,summary!$A10) -> 150 | D10: =SUMIFS('fact forecasts'!$L:$L,'fact forecasts'!$A:$A,summary!$A10) -> 4410 | E10: =SUMIFS('fact forecasts'!$M:$M,'fact forecasts'!$A:$A,summary!$A10) -> 3969 | F10: =SUMIFS(actuals!$G:$G,actuals!$A:$A,summary!$A10) -> 94 | G10: =SUMIFS(actuals!$J:$J,actuals!$A:$A,summary!$A10) -> 3066 | H10: =SUMIFS(actuals!$K:$K,actuals!$A:$A,summary!$A10) -> 2759.4 | I10: =SUMIFS('fact forecasts'!$I:$I,'fact forecasts'!$A:$A,summary!$A10,'fact forecasts'!$G:$G,">"&summary!$G$1) -> 50 | J10: =SUMIFS('fact forecasts'!$L:$L,'fact forecasts'!$A:$A,summary!$A10,'fact forecasts'!$G:$G,">"&summary!$G$1) -> 1470 | K10: =SUMIFS('fact forecasts'!$M:$M,'fact forecasts'!$A:$A,summary!$A10,'fact forecasts'!$G:$G,">"&summary!$G$1) -> 1323 | L10: =F10+I10 -> 144 | M10: =G10+J10 -> 4536 | N10: =H10+K10 -> 4082.4 | O10: =L10-C10 -> -6 | P10: =M10-D10 -> 126 | Q10: =N10-E10 -> 113.4
A11: T-107 | B11: Back-end development | C11: =SUMIFS('fact forecasts'!$I:$I,'fact forecasts'!$A:$A,summary!$A11) -> 150 | D11: =SUMIFS('fact forecasts'!$L:$L,'fact forecasts'!$A:$A,summary!$A11) -> 6930 | E11: =SUMIFS('fact forecasts'!$M:$M,'fact forecasts'!$A:$A,summary!$A11) -> 6237 | F11: =SUMIFS(actuals!$G:$G,actuals!$A:$A,summary!$A11) -> 95 | G11: =SUMIFS(actuals!$J:$J,actuals!$A:$A,summary!$A11) -> 4473 | H11: =SUMIFS(actuals!$K:$K,actuals!$A:$A,summary!$A11) -> 4025.7 | I11: =SUMIFS('fact forecasts'!$I:$I,'fact forecasts'!$A:$A,summary!$A11,'fact forecasts'!$G:$G,">"&summary!$G$1) -> 50 | J11: =SUMIFS('fact forecasts'!$L:$L,'fact forecasts'!$A:$A,summary!$A11,'fact forecasts'!$G:$G,">"&summary!$G$1) -> 2310 | K11: =SUMIFS('fact forecasts'!$M:$M,'fact forecasts'!$A:$A,summary!$A11,'fact forecasts'!$G:$G,">"&summary!$G$1) -> 2079 | L11: =F11+I11 -> 145 | M11: =G11+J11 -> 6783 | N11: =H11+K11 -> 6104.7 | O11: =L11-C11 -> -5 | P11: =M11-D11 -> -147 | Q11: =N11-E11 -> -132.3
A12: T-108 | B12: Unit testing | C12: =SUMIFS('fact forecasts'!$I:$I,'fact forecasts'!$A:$A,summary!$A12) -> 100 | D12: =SUMIFS('fact forecasts'!$L:$L,'fact forecasts'!$A:$A,summary!$A12) -> 2940 | E12: =SUMIFS('fact forecasts'!$M:$M,'fact forecasts'!$A:$A,summary!$A12) -> 2646 | F12: =SUMIFS(actuals!$G:$G,actuals!$A:$A,summary!$A12) -> 0 | G12: =SUMIFS(actuals!$J:$J,actuals!$A:$A,summary!$A12) -> 0 | H12: =SUMIFS(actuals!$K:$K,actuals!$A:$A,summary!$A12) -> 0 | I12: =SUMIFS('fact forecasts'!$I:$I,'fact forecasts'!$A:$A,summary!$A12,'fact forecasts'!$G:$G,">"&summary!$G$1) -> 100 | J12: =SUMIFS('fact forecasts'!$L:$L,'fact forecasts'!$A:$A,summary!$A12,'fact forecasts'!$G:$G,">"&summary!$G$1) -> 2940 | K12: =SUMIFS('fact forecasts'!$M:$M,'fact forecasts'!$A:$A,summary!$A12,'fact forecasts'!$G:$G,">"&summary!$G$1) -> 2646 | L12: =F12+I12 -> 100 | M12: =G12+J12 -> 2940 | N12: =H12+K12 -> 2646 | O12: =L12-C12 -> 0 | P12: =M12-D12 -> 0 | Q12: =N12-E12 -> 0
A13: T-109 | B13: Integration testing | C13: =SUMIFS('fact forecasts'!$I:$I,'fact forecasts'!$A:$A,summary!$A13) -> 100 | D13: =SUMIFS('fact forecasts'!$L:$L,'fact forecasts'!$A:$A,summary!$A13) -> 2940 | E13: =SUMIFS('fact forecasts'!$M:$M,'fact forecasts'!$A:$A,summary!$A13) -> 2646 | F13: =SUMIFS(actuals!$G:$G,actuals!$A:$A,summary!$A13) -> 0 | G13: =SUMIFS(actuals!$J:$J,actuals!$A:$A,summary!$A13) -> 0 | H13: =SUMIFS(actuals!$K:$K,actuals!$A:$A,summary!$A13) -> 0 | I13: =SUMIFS('fact forecasts'!$I:$I,'fact forecasts'!$A:$A,summary!$A13,'fact forecasts'!$G:$G,">"&summary!$G$1) -> 100 | J13: =SUMIFS('fact forecasts'!$L:$L,'fact forecasts'!$A:$A,summary!$A13,'fact forecasts'!$G:$G,">"&summary!$G$1) -> 2940 | K13: =SUMIFS('fact forecasts'!$M:$M,'fact forecasts'!$A:$A,summary!$A13,'fact forecasts'!$G:$G,">"&summary!$G$1) -> 2646 | L13: =F13+I13 -> 100 | M13: =G13+J13 -> 2940 | N13: =H13+K13 -> 2646 | O13: =L13-C13 -> 0 | P13: =M13-D13 -> 0 | Q13: =N13-E13 -> 0
A14: T-110 | B14: User acceptance testing | C14: =SUMIFS('fact forecasts'!$I:$I,'fact forecasts'!$A:$A,summary!$A14) -> 100 | D14: =SUMIFS('fact forecasts'!$L:$L,'fact forecasts'!$A:$A,summary!$A14) -> 3360 | E14: =SUMIFS('fact forecasts'!$M:$M,'fact forecasts'!$A:$A,summary!$A14) -> 3024 | F14: =SUMIFS(actuals!$G:$G,actuals!$A:$A,summary!$A14) -> 0 | G14: =SUMIFS(actuals!$J:$J,actuals!$A:$A,summary!$A14) -> 0 | H14: =SUMIFS(actuals!$K:$K,actuals!$A:$A,summary!$A14) -> 0 | I14: =SUMIFS('fact forecasts'!$I:$I,'fact forecasts'!$A:$A,summary!$A14,'fact forecasts'!$G:$G,">"&summary!$G$1) -> 100 | J14: =SUMIFS('fact forecasts'!$L:$L,'fact forecasts'!$A:$A,summary!$A14,'fact forecasts'!$G:$G,">"&summary!$G$1) -> 3360 | K14: =SUMIFS('fact forecasts'!$M:$M,'fact forecasts'!$A:$A,summary!$A14,'fact forecasts'!$G:$G,">"&summary!$G$1) -> 3024 | L14: =F14+I14 -> 100 | M14: =G14+J14 -> 3360 | N14: =H14+K14 -> 3024 | O14: =L14-C14 -> 0 | P14: =M14-D14 -> 0 | Q14: =N14-E14 -> 0
A15: T-111 | B15: Production deployment | C15: =SUMIFS('fact forecasts'!$I:$I,'fact forecasts'!$A:$A,summary!$A15) -> 100 | D15: =SUMIFS('fact forecasts'!$L:$L,'fact forecasts'!$A:$A,summary!$A15) -> 7140 | E15: =SUMIFS('fact forecasts'!$M:$M,'fact forecasts'!$A:$A,summary!$A15) -> 6426 | F15: =SUMIFS(actuals!$G:$G,actuals!$A:$A,summary!$A15) -> 0 | G15: =SUMIFS(actuals!$J:$J,actuals!$A:$A,summary!$A15) -> 0 | H15: =SUMIFS(actuals!$K:$K,actuals!$A:$A,summary!$A15) -> 0 | I15: =SUMIFS('fact forecasts'!$I:$I,'fact forecasts'!$A:$A,summary!$A15,'fact forecasts'!$G:$G,">"&summary!$G$1) -> 100 | J15: =SUMIFS('fact forecasts'!$L:$L,'fact forecasts'!$A:$A,summary!$A15,'fact forecasts'!$G:$G,">"&summary!$G$1) -> 7140 | K15: =SUMIFS('fact forecasts'!$M:$M,'fact forecasts'!$A:$A,summary!$A15,'fact forecasts'!$G:$G,">"&summary!$G$1) -> 6426 | L15: =F15+I15 -> 100 | M15: =G15+J15 -> 7140 | N15: =H15+K15 -> 6426 | O15: =L15-C15 -> 0 | P15: =M15-D15 -> 0 | Q15: =N15-E15 -> 0
A16: T-112 | B16: Project closure | C16: =SUMIFS('fact forecasts'!$I:$I,'fact forecasts'!$A:$A,summary!$A16) -> 15 | D16: =SUMIFS('fact forecasts'!$L:$L,'fact forecasts'!$A:$A,summary!$A16) -> 1365 | E16: =SUMIFS('fact forecasts'!$M:$M,'fact forecasts'!$A:$A,summary!$A16) -> 1228.5 | F16: =SUMIFS(actuals!$G:$G,actuals!$A:$A,summary!$A16) -> 0 | G16: =SUMIFS(actuals!$J:$J,actuals!$A:$A,summary!$A16) -> 0 | H16: =SUMIFS(actuals!$K:$K,actuals!$A:$A,summary!$A16) -> 0 | I16: =SUMIFS('fact forecasts'!$I:$I,'fact forecasts'!$A:$A,summary!$A16,'fact forecasts'!$G:$G,">"&summary!$G$1) -> 15 | J16: =SUMIFS('fact forecasts'!$L:$L,'fact forecasts'!$A:$A,summary!$A16,'fact forecasts'!$G:$G,">"&summary!$G$1) -> 1365 | K16: =SUMIFS('fact forecasts'!$M:$M,'fact forecasts'!$A:$A,summary!$A16,'fact forecasts'!$G:$G,">"&summary!$G$1) -> 1228.5 | L16: =F16+I16 -> 15 | M16: =G16+J16 -> 1365 | N16: =H16+K16 -> 1228.5 | O16: =L16-C16 -> 0 | P16: =M16-D16 -> 0 | Q16: =N16-E16 -> 0
A17: T-Con | B17: Contingency | D17: 1915 | F17: =SUMIFS(actuals!$G:$G,actuals!$A:$A,summary!$A17) -> 0 | G17: =SUMIFS(actuals!$J:$J,actuals!$A:$A,summary!$A17) -> 0 | H17: =SUMIFS(actuals!$K:$K,actuals!$A:$A,summary!$A17) -> 0 | I17: =SUMIFS('fact forecasts'!$I:$I,'fact forecasts'!$A:$A,summary!$A17,'fact forecasts'!$G:$G,">"&summary!$G$1) -> 0 | J17: =SUMIFS('fact forecasts'!$L:$L,'fact forecasts'!$A:$A,summary!$A17,'fact forecasts'!$G:$G,">"&summary!$G$1) -> 0 | K17: =SUMIFS('fact forecasts'!$M:$M,'fact forecasts'!$A:$A,summary!$A17,'fact forecasts'!$G:$G,">"&summary!$G$1) -> 0 | M17: 2408 | O17: =L17-C17 -> 0 | P17: =M17-D17 -> 493

Sheet actuals
A1: actuals
A2: Task Code | B2: Task Name | C2: Employee Title | D2: Employee Number | E2: Employee Name | F2: Week Ending | G2: Hours | H2: Bill Rate/Hour | I2: FLBR Rate/Hour | J2: Forecast Bill | K2: Forecast FBLR
A3: T-101 | B3: Requirements gathering | C3: Director | D3: 1 | E3: Ethan Carter | F3: 46207 | G3: 7 | H3: 100 | I3: 90 | J3: =Actuals[[#This Row],[Hours]]*Actuals[[#This Row],[Bill Rate/Hour]] -> 700 | K3: =Actuals[[#This Row],[Hours]]*Actuals[[#This Row],[FLBR Rate/Hour]] -> 630
A4: T-101 | B4: Requirements gathering | C4: Director | D4: 1 | E4: Ethan Carter | F4: 46214 | G4: 5 | H4: 100 | I4: 90 | J4: =Actuals[[#This Row],[Hours]]*Actuals[[#This Row],[Bill Rate/Hour]] -> 500 | K4: =Actuals[[#This Row],[Hours]]*Actuals[[#This Row],[FLBR Rate/Hour]] -> 450
A5: T-102 | B5: Scope definition | C5: Director | D5: 1 | E5: Ethan Carter | F5: 46214 | G5: 5 | H5: 100 | I5: 90 | J5: =Actuals[[#This Row],[Hours]]*Actuals[[#This Row],[Bill Rate/Hour]] -> 500 | K5: =Actuals[[#This Row],[Hours]]*Actuals[[#This Row],[FLBR Rate/Hour]] -> 450
A6: T-102 | B6: Scope definition | C6: Director | D6: 1 | E6: Ethan Carter | F6: 46221 | G6: 8 | H6: 100 | I6: 90 | J6: =Actuals[[#This Row],[Hours]]*Actuals[[#This Row],[Bill Rate/Hour]] -> 800 | K6: =Actuals[[#This Row],[Hours]]*Actuals[[#This Row],[FLBR Rate/Hour]] -> 720
A7: T-101 | B7: Requirements gathering | C7: Director | D7: 2 | E7: Olivia Bennett | F7: 46207 | G7: 8 | H7: 100 | I7: 90 | J7: =Actuals[[#This Row],[Hours]]*Actuals[[#This Row],[Bill Rate/Hour]] -> 800 | K7: =Actuals[[#This Row],[Hours]]*Actuals[[#This Row],[FLBR Rate/Hour]] -> 720
A8: T-101 | B8: Requirements gathering | C8: Director | D8: 2 | E8: Olivia Bennett | F8: 46214 | G8: 8 | H8: 100 | I8: 90 | J8: =Actuals[[#This Row],[Hours]]*Actuals[[#This Row],[Bill Rate/Hour]] -> 800 | K8: =Actuals[[#This Row],[Hours]]*Actuals[[#This Row],[FLBR Rate/Hour]] -> 720
A9: T-103 | B9: Project planning | C9: Director | D9: 2 | E9: Olivia Bennett | F9: 46214 | G9: 11 | H9: 100 | I9: 90 | J9: =Actuals[[#This Row],[Hours]]*Actuals[[#This Row],[Bill Rate/Hour]] -> 1100 | K9: =Actuals[[#This Row],[Hours]]*Actuals[[#This Row],[FLBR Rate/Hour]] -> 990
A10: T-103 | B10: Project planning | C10: Director | D10: 2 | E10: Olivia Bennett | F10: 46221 | G10: 9 | H10: 100 | I10: 90 | J10: =Actuals[[#This Row],[Hours]]*Actuals[[#This Row],[Bill Rate/Hour]] -> 900 | K10: =Actuals[[#This Row],[Hours]]*Actuals[[#This Row],[FLBR Rate/Hour]] -> 810
A11: T-103 | B11: Project planning | C11: Manager | D11: 3 | E11: Liam Foster | F11: 46214 | G11: 18 | H11: 80 | I11: 72 | J11: =Actuals[[#This Row],[Hours]]*Actuals[[#This Row],[Bill Rate/Hour]] -> 1440 | K11: =Actuals[[#This Row],[Hours]]*Actuals[[#This Row],[FLBR Rate/Hour]] -> 1296
A12: T-103 | B12: Project planning | C12: Manager | D12: 3 | E12: Liam Foster | F12: 46221 | G12: 17 | H12: 80 | I12: 72 | J12: =Actuals[[#This Row],[Hours]]*Actuals[[#This Row],[Bill Rate/Hour]] -> 1360 | K12: =Actuals[[#This Row],[Hours]]*Actuals[[#This Row],[FLBR Rate/Hour]] -> 1224
A13: T-105 | B13: Database design | C13: Manager | D13: 3 | E13: Liam Foster | F13: 46228 | G13: 13 | H13: 80 | I13: 72 | J13: =Actuals[[#This Row],[Hours]]*Actuals[[#This Row],[Bill Rate/Hour]] -> 1040 | K13: =Actuals[[#This Row],[Hours]]*Actuals[[#This Row],[FLBR Rate/Hour]] -> 936
A14: T-105 | B14: Database design | C14: Manager | D14: 3 | E14: Liam Foster | F14: 46235 | G14: 11 | H14: 84 | I14: 75.6 | J14: =Actuals[[#This Row],[Hours]]*Actuals[[#This Row],[Bill Rate/Hour]] -> 924 | K14: =Actuals[[#This Row],[Hours]]*Actuals[[#This Row],[FLBR Rate/Hour]] -> 831.6
... A30: T-107 | B30: Back-end development | C30: Engineer | D30: 7 | E30: Mason Reed | F30: 46249 | G30: 33 | H30: 42 | I30: 37.8 | J30: =Actuals[[#This Row],[Hours]]*Actuals[[#This Row],[Bill Rate/Hour]] -> 1386 | K30: =Actuals[[#This Row],[Hours]]*Actuals[[#This Row],[FLBR Rate/Hour]] -> 1247.4

Sheet input forecasts
A1: input forecasts
K2: =SUM(Input_Forecast[Forecast Bill]) -> 48825 | L2: =SUM(Input_Forecast[Forecast FBLR]) -> 43942.5 | M2: =SUM(Input_Forecast[Forecast Hours]) -> 955 | N2: =_xlfn.XLOOKUP(N$3,'dim dates'!$A:$A,'dim dates'!$B:$B) -> 46207 | O2: =_xlfn.XLOOKUP(O$3,'dim dates'!$A:$A,'dim dates'!$B:$B) -> 46214 | P2: =_xlfn.XLOOKUP(P$3,'dim dates'!$A:$A,'dim dates'!$B:$B) -> 46221 | Q2: =_xlfn.XLOOKUP(Q$3,'dim dates'!$A:$A,'dim dates'!$B:$B) -> 46228 | R2: =_xlfn.XLOOKUP(R$3,'dim dates'!$A:$A,'dim dates'!$B:$B) -> 46235 | S2: =_xlfn.XLOOKUP(S$3,'dim dates'!$A:$A,'dim dates'!$B:$B) -> 46242 | T2: =_xlfn.XLOOKUP(T$3,'dim dates'!$A:$A,'dim dates'!$B:$B) -> 46249 | U2: =_xlfn.XLOOKUP(U$3,'dim dates'!$A:$A,'dim dates'!$B:$B) -> 46256 | ... Z2: =_xlfn.XLOOKUP(Z$3,'dim dates'!$A:$A,'dim dates'!$B:$B) -> 46291
A3: Task Code | B3: Task Name | C3: Employee Title | D3: Employee Number | E3: Employee Name | F3: Bill Rate/Hour | G3: FBLR/Hour | H3: Actuals To Date Hours | I3: Actuals To Date Bill | J3: Actuals To Date FBLR | K3: Forecast Bill | L3: Forecast FBLR | M3: Forecast Hours | N3: W1 | O3: W2 | P3: W3 | Q3: W4 | R3: W5 | S3: W6 | T3: W7 | U3: W8 | V3: W9 | W3: W10 | X3: W11 | Y3: W12 | Z3: W13
A4: T-101 | B4: =_xlfn.XLOOKUP('input forecasts'!$A4,'dim tasks'!$A:$A,'dim tasks'!$B:$B,"") -> Requirements gathering | C4: =_xlfn.XLOOKUP($E4,'dim employees'!$C:$C,'dim employees'!$A:$A,"") -> Director | D4: =_xlfn.XLOOKUP($E4,'dim employees'!$C:$C,'dim employees'!$B:$B,"") -> 1 | E4: Ethan Carter | F4: =IFERROR(_xlfn.MAXIFS('dim rates'!$D:$D,'dim rates'!$B:$B,'input forecasts'!$D4,'dim rates'!$A:$A,F$3),"") -> 105 | G4: =IFERROR(_xlfn.MAXIFS('dim rates'!$D:$D,'dim rates'!$B:$B,'input forecasts'!$D4,'dim rates'!$A:$A,G$3),"") -> 94.5 | H4: =SUMIFS(actuals!$G:$G,actuals!$A:$A,$A4,actuals!$D:$D,$D4) -> 12 | I4: =SUMIFS(actuals!$J:$J,actuals!$A:$A,$A4,actuals!$D:$D,$D4) -> 1200 | J4: =SUMIFS(actuals!$K:$K,actuals!$A:$A,$A4,actuals!$D:$D,$D4) -> 1080 | K4: =Input_Forecast[[#This Row],[Bill Rate/Hour]]*Input_Forecast[[#This Row],[Forecast Hours]] -> 1050 | L4: =Input_Forecast[[#This Row],[FBLR/Hour]]*Input_Forecast[[#This Row],[Forecast Hours]] -> 945 | M4: =SUM(Input_Forecast[[#This Row],[W1]:[W13]]) -> 10 | N4: 5 | O4: 5
A5: T-101 | B5: =_xlfn.XLOOKUP('input forecasts'!$A5,'dim tasks'!$A:$A,'dim tasks'!$B:$B,"") -> Requirements gathering | C5: =_xlfn.XLOOKUP($E5,'dim employees'!$C:$C,'dim employees'!$A:$A,"") -> Director | D5: =_xlfn.XLOOKUP($E5,'dim employees'!$C:$C,'dim employees'!$B:$B,"") -> 2 | E5: Olivia Bennett | F5: =IFERROR(_xlfn.MAXIFS('dim rates'!$D:$D,'dim rates'!$B:$B,'input forecasts'!$D5,'dim rates'!$A:$A,F$3),"") -> 105 | G5: =IFERROR(_xlfn.MAXIFS('dim rates'!$D:$D,'dim rates'!$B:$B,'input forecasts'!$D5,'dim rates'!$A:$A,G$3),"") -> 94.5 | H5: =SUMIFS(actuals!$G:$G,actuals!$A:$A,$A5,actuals!$D:$D,$D5) -> 16 | I5: =SUMIFS(actuals!$J:$J,actuals!$A:$A,$A5,actuals!$D:$D,$D5) -> 1600 | J5: =SUMIFS(actuals!$K:$K,actuals!$A:$A,$A5,actuals!$D:$D,$D5) -> 1440 | K5: =Input_Forecast[[#This Row],[Bill Rate/Hour]]*Input_Forecast[[#This Row],[Forecast Hours]] -> 2100 | L5: =Input_Forecast[[#This Row],[FBLR/Hour]]*Input_Forecast[[#This Row],[Forecast Hours]] -> 1890 | M5: =SUM(Input_Forecast[[#This Row],[W1]:[W13]]) -> 20 | N5: 10 | O5: 10
B6: =_xlfn.XLOOKUP('input forecasts'!$A6,'dim tasks'!$A:$A,'dim tasks'!$B:$B,"") -> 0 | C6: =_xlfn.XLOOKUP($E6,'dim employees'!$C:$C,'dim employees'!$A:$A,"") -> 0 | D6: =_xlfn.XLOOKUP($E6,'dim employees'!$C:$C,'dim employees'!$B:$B,"") -> 0 | F6: =IFERROR(_xlfn.MAXIFS('dim rates'!$D:$D,'dim rates'!$B:$B,'input forecasts'!$D6,'dim rates'!$A:$A,F$3),"") -> 0 | G6: =IFERROR(_xlfn.MAXIFS('dim rates'!$D:$D,'dim rates'!$B:$B,'input forecasts'!$D6,'dim rates'!$A:$A,G$3),"") -> 0 | H6: =SUMIFS(actuals!$G:$G,actuals!$A:$A,$A6,actuals!$D:$D,$D6) -> 0 | I6: =SUMIFS(actuals!$J:$J,actuals!$A:$A,$A6,actuals!$D:$D,$D6) -> 0 | J6: =SUMIFS(actuals!$K:$K,actuals!$A:$A,$A6,actuals!$D:$D,$D6) -> 0 | K6: =Input_Forecast[[#This Row],[Bill Rate/Hour]]*Input_Forecast[[#This Row],[Forecast Hours]] -> 0 | L6: =Input_Forecast[[#This Row],[FBLR/Hour]]*Input_Forecast[[#This Row],[Forecast Hours]] -> 0 | M6: =SUM(Input_Forecast[[#This Row],[W1]:[W13]]) -> 0
A7: T-102 | B7: =_xlfn.XLOOKUP('input forecasts'!$A7,'dim tasks'!$A:$A,'dim tasks'!$B:$B,"") -> Scope definition | C7: =_xlfn.XLOOKUP($E7,'dim employees'!$C:$C,'dim employees'!$A:$A,"") -> Director | D7: =_xlfn.XLOOKUP($E7,'dim employees'!$C:$C,'dim employees'!$B:$B,"") -> 1 | E7: Ethan Carter | F7: =IFERROR(_xlfn.MAXIFS('dim rates'!$D:$D,'dim rates'!$B:$B,'input forecasts'!$D7,'dim rates'!$A:$A,F$3),"") -> 105 | G7: =IFERROR(_xlfn.MAXIFS('dim rates'!$D:$D,'dim rates'!$B:$B,'input forecasts'!$D7,'dim rates'!$A:$A,G$3),"") -> 94.5 | H7: =SUMIFS(actuals!$G:$G,actuals!$A:$A,$A7,actuals!$D:$D,$D7) -> 13 | I7: =SUMIFS(actuals!$J:$J,actuals!$A:$A,$A7,actuals!$D:$D,$D7) -> 1300 | J7: =SUMIFS(actuals!$K:$K,actuals!$A:$A,$A7,actuals!$D:$D,$D7) -> 1170 | K7: =Input_Forecast[[#This Row],[Bill Rate/Hour]]*Input_Forecast[[#This Row],[Forecast Hours]] -> 1050 | L7: =Input_Forecast[[#This Row],[FBLR/Hour]]*Input_Forecast[[#This Row],[Forecast Hours]] -> 945 | M7: =SUM(Input_Forecast[[#This Row],[W1]:[W13]]) -> 10 | O7: 5 | P7: 5
A8: T-102 | B8: =_xlfn.XLOOKUP('input forecasts'!$A8,'dim tasks'!$A:$A,'dim tasks'!$B:$B,"") -> Scope definition | C8: =_xlfn.XLOOKUP($E8,'dim employees'!$C:$C,'dim employees'!$A:$A,"") -> Manager | D8: =_xlfn.XLOOKUP($E8,'dim employees'!$C:$C,'dim employees'!$B:$B,"") -> 4 | E8: Sophia Mitchell | F8: =IFERROR(_xlfn.MAXIFS('dim rates'!$D:$D,'dim rates'!$B:$B,'input forecasts'!$D8,'dim rates'!$A:$A,F$3),"") -> 84 | G8: =IFERROR(_xlfn.MAXIFS('dim rates'!$D:$D,'dim rates'!$B:$B,'input forecasts'!$D8,'dim rates'!$A:$A,G$3),"") -> 75.6 | H8: =SUMIFS(actuals!$G:$G,actuals!$A:$A,$A8,actuals!$D:$D,$D8) -> 21 | I8: =SUMIFS(actuals!$J:$J,actuals!$A:$A,$A8,actuals!$D:$D,$D8) -> 1680 | J8: =SUMIFS(actuals!$K:$K,actuals!$A:$A,$A8,actuals!$D:$D,$D8) -> 1512 | K8: =Input_Forecast[[#This Row],[Bill Rate/Hour]]*Input_Forecast[[#This Row],[Forecast Hours]] -> 1680 | L8: =Input_Forecast[[#This Row],[FBLR/Hour]]*Input_Forecast[[#This Row],[Forecast Hours]] -> 1512 | M8: =SUM(Input_Forecast[[#This Row],[W1]:[W13]]) -> 20 | O8: 10 | P8: 10
B9: =_xlfn.XLOOKUP('input forecasts'!$A9,'dim tasks'!$A:$A,'dim tasks'!$B:$B,"") -> 0 | C9: =_xlfn.XLOOKUP($E9,'dim employees'!$C:$C,'dim employees'!$A:$A,"") -> 0 | D9: =_xlfn.XLOOKUP($E9,'dim employees'!$C:$C,'dim employees'!$B:$B,"") -> 0 | F9: =IFERROR(_xlfn.MAXIFS('dim rates'!$D:$D,'dim rates'!$B:$B,'input forecasts'!$D9,'dim rates'!$A:$A,F$3),"") -> 0 | G9: =IFERROR(_xlfn.MAXIFS('dim rates'!$D:$D,'dim rates'!$B:$B,'input forecasts'!$D9,'dim rates'!$A:$A,G$3),"") -> 0 | H9: =SUMIFS(actuals!$G:$G,actuals!$A:$A,$A9,actuals!$D:$D,$D9) -> 0 | I9: =SUMIFS(actuals!$J:$J,actuals!$A:$A,$A9,actuals!$D:$D,$D9) -> 0 | J9: =SUMIFS(actuals!$K:$K,actuals!$A:$A,$A9,actuals!$D:$D,$D9) -> 0 | K9: =Input_Forecast[[#This Row],[Bill Rate/Hour]]*Input_Forecast[[#This Row],[Forecast Hours]] -> 0 | L9: =Input_Forecast[[#This Row],[FBLR/Hour]]*Input_Forecast[[#This Row],[Forecast Hours]] -> 0 | M9: =SUM(Input_Forecast[[#This Row],[W1]:[W13]]) -> 0
A10: T-103 | B10: =_xlfn.XLOOKUP('input forecasts'!$A10,'dim tasks'!$A:$A,'dim tasks'!$B:$B,"") -> Project planning | C10: =_xlfn.XLOOKUP($E10,'dim employees'!$C:$C,'dim employees'!$A:$A,"") -> Director | D10: =_xlfn.XLOOKUP($E10,'dim employees'!$C:$C,'dim employees'!$B:$B,"") -> 2 | E10: Olivia Bennett | F10: =IFERROR(_xlfn.MAXIFS('dim rates'!$D:$D,'dim rates'!$B:$B,'input forecasts'!$D10,'dim rates'!$A:$A,F$3),"") -> 105 | G10: =IFERROR(_xlfn.MAXIFS('dim rates'!$D:$D,'dim rates'!$B:$B,'input forecasts'!$D10,'dim rates'!$A:$A,G$3),"") -> 94.5 | H10: =SUMIFS(actuals!$G:$G,actuals!$A:$A,$A10,actuals!$D:$D,$D10) -> 20 | I10: =SUMIFS(actuals!$J:$J,actuals!$A:$A,$A10,actuals!$D:$D,$D10) -> 2000 | J10: =SUMIFS(actuals!$K:$K,actuals!$A:$A,$A10,actuals!$D:$D,$D10) -> 1800 | K10: =Input_Forecast[[#This Row],[Bill Rate/Hour]]*Input_Forecast[[#This Row],[Forecast Hours]] -> 2100 | L10: =Input_Forecast[[#This Row],[FBLR/Hour]]*Input_Forecast[[#This Row],[Forecast Hours]] -> 1890 | M10: =SUM(Input_Forecast[[#This Row],[W1]:[W13]]) -> 20 | O10: 10 | P10: 10
A11: T-103 | B11: =_xlfn.XLOOKUP('input forecasts'!$A11,'dim tasks'!$A:$A,'dim tasks'!$B:$B,"") -> Project planning | C11: =_xlfn.XLOOKUP($E11,'dim employees'!$C:$C,'dim employees'!$A:$A,"") -> Manager | D11: =_xlfn.XLOOKUP($E11,'dim employees'!$C:$C,'dim employees'!$B:$B,"") -> 3 | E11: Liam Foster | F11: =IFERROR(_xlfn.MAXIFS('dim rates'!$D:$D,'dim rates'!$B:$B,'input forecasts'!$D11,'dim rates'!$A:$A,F$3),"") -> 84 | G11: =IFERROR(_xlfn.MAXIFS('dim rates'!$D:$D,'dim rates'!$B:$B,'input forecasts'!$D11,'dim rates'!$A:$A,G$3),"") -> 75.6 | H11: =SUMIFS(actuals!$G:$G,actuals!$A:$A,$A11,actuals!$D:$D,$D11) -> 35 | I11: =SUMIFS(actuals!$J:$J,actuals!$A:$A,$A11,actuals!$D:$D,$D11) -> 2800 | J11: =SUMIFS(actuals!$K:$K,actuals!$A:$A,$A11,actuals!$D:$D,$D11) -> 2520 | K11: =Input_Forecast[[#This Row],[Bill Rate/Hour]]*Input_Forecast[[#This Row],[Forecast Hours]] -> 3360 | L11: =Input_Forecast[[#This Row],[FBLR/Hour]]*Input_Forecast[[#This Row],[Forecast Hours]] -> 3024 | M11: =SUM(Input_Forecast[[#This Row],[W1]:[W13]]) -> 40 | O11: 20 | P11: 20
B12: =_xlfn.XLOOKUP('input forecasts'!$A12,'dim tasks'!$A:$A,'dim tasks'!$B:$B,"") -> 0 | C12: =_xlfn.XLOOKUP($E12,'dim employees'!$C:$C,'dim employees'!$A:$A,"") -> 0 | D12: =_xlfn.XLOOKUP($E12,'dim employees'!$C:$C,'dim employees'!$B:$B,"") -> 0 | F12: =IFERROR(_xlfn.MAXIFS('dim rates'!$D:$D,'dim rates'!$B:$B,'input forecasts'!$D12,'dim rates'!$A:$A,F$3),"") -> 0 | G12: =IFERROR(_xlfn.MAXIFS('dim rates'!$D:$D,'dim rates'!$B:$B,'input forecasts'!$D12,'dim rates'!$A:$A,G$3),"") -> 0 | H12: =SUMIFS(actuals!$G:$G,actuals!$A:$A,$A12,actuals!$D:$D,$D12) -> 0 | I12: =SUMIFS(actuals!$J:$J,actuals!$A:$A,$A12,actuals!$D:$D,$D12) -> 0 | J12: =SUMIFS(actuals!$K:$K,actuals!$A:$A,$A12,actuals!$D:$D,$D12) -> 0 | K12: =Input_Forecast[[#This Row],[Bill Rate/Hour]]*Input_Forecast[[#This Row],[Forecast Hours]] -> 0 | L12: =Input_Forecast[[#This Row],[FBLR/Hour]]*Input_Forecast[[#This Row],[Forecast Hours]] -> 0 | M12: =SUM(Input_Forecast[[#This Row],[W1]:[W13]]) -> 0
A13: T-104 | B13: =_xlfn.XLOOKUP('input forecasts'!$A13,'dim tasks'!$A:$A,'dim tasks'!$B:$B,"") -> Solution design | C13: =_xlfn.XLOOKUP($E13,'dim employees'!$C:$C,'dim employees'!$A:$A,"") -> Manager | D13: =_xlfn.XLOOKUP($E13,'dim employees'!$C:$C,'dim employees'!$B:$B,"") -> 4 | E13: Sophia Mitchell | F13: =IFERROR(_xlfn.MAXIFS('dim rates'!$D:$D,'dim rates'!$B:$B,'input forecasts'!$D13,'dim rates'!$A:$A,F$3),"") -> 84 | G13: =IFERROR(_xlfn.MAXIFS('dim rates'!$D:$D,'dim rates'!$B:$B,'input forecasts'!$D13,'dim rates'!$A:$A,G$3),"") -> 75.6 | H13: =SUMIFS(actuals!$G:$G,actuals!$A:$A,$A13,actuals!$D:$D,$D13) -> 19 | I13: =SUMIFS(actuals!$J:$J,actuals!$A:$A,$A13,actuals!$D:$D,$D13) -> 1580 | J13: =SUMIFS(actuals!$K:$K,actuals!$A:$A,$A13,actuals!$D:$D,$D13) -> 1422 | K13: =Input_Forecast[[#This Row],[Bill Rate/Hour]]*Input_Forecast[[#This Row],[Forecast Hours]] -> 1680 | L13: =Input_Forecast[[#This Row],[FBLR/Hour]]*Input_Forecast[[#This Row],[Forecast Hours]] -> 1512 | M13: =SUM(Input_Forecast[[#This Row],[W1]:[W13]]) -> 20 | Q13: 10 | R13: 10
A14: T-104 | B14: =_xlfn.XLOOKUP('input forecasts'!$A14,'dim tasks'!$A:$A,'dim tasks'!$B:$B,"") -> Solution design | C14: =_xlfn.XLOOKUP($E14,'dim employees'!$C:$C,'dim employees'!$A:$A,"") -> Senior Engineer | D14: =_xlfn.XLOOKUP($E14,'dim employees'!$C:$C,'dim employees'!$B:$B,"") -> 5 | E14: Noah Turner | F14: =IFERROR(_xlfn.MAXIFS('dim rates'!$D:$D,'dim rates'!$B:$B,'input forecasts'!$D14,'dim rates'!$A:$A,F$3),"") -> 63 | G14: =IFERROR(_xlfn.MAXIFS('dim rates'!$D:$D,'dim rates'!$B:$B,'input forecasts'!$D14,'dim rates'!$A:$A,G$3),"") -> 56.7 | H14: =SUMIFS(actuals!$G:$G,actuals!$A:$A,$A14,actuals!$D:$D,$D14) -> 36 | I14: =SUMIFS(actuals!$J:$J,actuals!$A:$A,$A14,actuals!$D:$D,$D14) -> 2205 | J14: =SUMIFS(actuals!$K:$K,actuals!$A:$A,$A14,actuals!$D:$D,$D14) -> 1984.5 | K14: =Input_Forecast[[#This Row],[Bill Rate/Hour]]*Input_Forecast[[#This Row],[Forecast Hours]] -> 2520 | L14: =Input_Forecast[[#This Row],[FBLR/Hour]]*Input_Forecast[[#This Row],[Forecast Hours]] -> 2268 | M14: =SUM(Input_Forecast[[#This Row],[W1]:[W13]]) -> 40 | Q14: 20 | R14: 20
B15: =_xlfn.XLOOKUP('input forecasts'!$A15,'dim tasks'!$A:$A,'dim tasks'!$B:$B,"") -> 0 | C15: =_xlfn.XLOOKUP($E15,'dim employees'!$C:$C,'dim employees'!$A:$A,"") -> 0 | D15: =_xlfn.XLOOKUP($E15,'dim employees'!$C:$C,'dim employees'!$B:$B,"") -> 0 | F15: =IFERROR(_xlfn.MAXIFS('dim rates'!$D:$D,'dim rates'!$B:$B,'input forecasts'!$D15,'dim rates'!$A:$A,F$3),"") -> 0 | G15: =IFERROR(_xlfn.MAXIFS('dim rates'!$D:$D,'dim rates'!$B:$B,'input forecasts'!$D15,'dim rates'!$A:$A,G$3),"") -> 0 | H15: =SUMIFS(actuals!$G:$G,actuals!$A:$A,$A15,actuals!$D:$D,$D15) -> 0 | I15: =SUMIFS(actuals!$J:$J,actuals!$A:$A,$A15,actuals!$D:$D,$D15) -> 0 | J15: =SUMIFS(actuals!$K:$K,actuals!$A:$A,$A15,actuals!$D:$D,$D15) -> 0 | K15: =Input_Forecast[[#This Row],[Bill Rate/Hour]]*Input_Forecast[[#This Row],[Forecast Hours]] -> 0 | L15: =Input_Forecast[[#This Row],[FBLR/Hour]]*Input_Forecast[[#This Row],[Forecast Hours]] -> 0 | M15: =SUM(Input_Forecast[[#This Row],[W1]:[W13]]) -> 0
A16: T-105 | B16: =_xlfn.XLOOKUP('input forecasts'!$A16,'dim tasks'!$A:$A,'dim tasks'!$B:$B,"") -> Database design | C16: =_xlfn.XLOOKUP($E16,'dim employees'!$C:$C,'dim employees'!$A:$A,"") -> Manager | D16: =_xlfn.XLOOKUP($E16,'dim employees'!$C:$C,'dim employees'!$B:$B,"") -> 3 | E16: Liam Foster | F16: =IFERROR(_xlfn.MAXIFS('dim rates'!$D:$D,'dim rates'!$B:$B,'input forecasts'!$D16,'dim rates'!$A:$A,F$3),"") -> 84 | G16: =IFERROR(_xlfn.MAXIFS('dim rates'!$D:$D,'dim rates'!$B:$B,'input forecasts'!$D16,'dim rates'!$A:$A,G$3),"") -> 75.6 | H16: =SUMIFS(actuals!$G:$G,actuals!$A:$A,$A16,actuals!$D:$D,$D16) -> 24 | I16: =SUMIFS(actuals!$J:$J,actuals!$A:$A,$A16,actuals!$D:$D,$D16) -> 1964 | J16: =SUMIFS(actuals!$K:$K,actuals!$A:$A,$A16,actuals!$D:$D,$D16) -> 1767.6 | K16: =Input_Forecast[[#This Row],[Bill Rate/Hour]]*Input_Forecast[[#This Row],[Forecast Hours]] -> 1680 | L16: =Input_Forecast[[#This Row],[FBLR/Hour]]*Input_Forecast[[#This Row],[Forecast Hours]] -> 1512 | M16: =SUM(Input_Forecast[[#This Row],[W1]:[W13]]) -> 20 | Q16: 10 | R16: 10
A17: T-105 | B17: =_xlfn.XLOOKUP('input forecasts'!$A17,'dim tasks'!$A:$A,'dim tasks'!$B:$B,"") -> Database design | C17: =_xlfn.XLOOKUP($E17,'dim employees'!$C:$C,'dim employees'!$A:$A,"") -> Senior Engineer | D17: =_xlfn.XLOOKUP($E17,'dim employees'!$C:$C,'dim employees'!$B:$B,"") -> 6 | E17: Amelia Brooks | F17: =IFERROR(_xlfn.MAXIFS('dim rates'!$D:$D,'dim rates'!$B:$B,'input forecasts'!$D17,'dim rates'!$A:$A,F$3),"") -> 63 | G17: =IFERROR(_xlfn.MAXIFS('dim rates'!$D:$D,'dim rates'!$B:$B,'input forecasts'!$D17,'dim rates'!$A:$A,G$3),"") -> 56.7 | H17: =SUMIFS(actuals!$G:$G,actuals!$A:$A,$A17,actuals!$D:$D,$D17) -> 36 | I17: =SUMIFS(actuals!$J:$J,actuals!$A:$A,$A17,actuals!$D:$D,$D17) -> 2199 | J17: =SUMIFS(actuals!$K:$K,actuals!$A:$A,$A17,actuals!$D:$D,$D17) -> 1979.1 | K17: =Input_Forecast[[#This Row],[Bill Rate/Hour]]*Input_Forecast[[#This Row],[Forecast Hours]] -> 2520 | L17: =Input_Forecast[[#This Row],[FBLR/Hour]]*Input_Forecast[[#This Row],[Forecast Hours]] -> 2268 | M17: =SUM(Input_Forecast[[#This Row],[W1]:[W13]]) -> 40 | Q17: 20 | R17: 20
B18: =_xlfn.XLOOKUP('input forecasts'!$A18,'dim tasks'!$A:$A,'dim tasks'!$B:$B,"") -> 0 | C18: =_xlfn.XLOOKUP($E18,'dim employees'!$C:$C,'dim employees'!$A:$A,"") -> 0 | D18: =_xlfn.XLOOKUP($E18,'dim employees'!$C:$C,'dim employees'!$B:$B,"") -> 0 | F18: =IFERROR(_xlfn.MAXIFS('dim rates'!$D:$D,'dim rates'!$B:$B,'input forecasts'!$D18,'dim rates'!$A:$A,F$3),"") -> 0 | G18: =IFERROR(_xlfn.MAXIFS('dim rates'!$D:$D,'dim rates'!$B:$B,'input forecasts'!$D18,'dim rates'!$A:$A,G$3),"") -> 0 | H18: =SUMIFS(actuals!$G:$G,actuals!$A:$A,$A18,actuals!$D:$D,$D18) -> 0 | I18: =SUMIFS(actuals!$J:$J,actuals!$A:$A,$A18,actuals!$D:$D,$D18) -> 0 | J18: =SUMIFS(actuals!$K:$K,actuals!$A:$A,$A18,actuals!$D:$D,$D18) -> 0 | K18: =Input_Forecast[[#This Row],[Bill Rate/Hour]]*Input_Forecast[[#This Row],[Forecast Hours]] -> 0 | L18: =Input_Forecast[[#This Row],[FBLR/Hour]]*Input_Forecast[[#This Row],[Forecast Hours]] -> 0 | M18: =SUM(Input_Forecast[[#This Row],[W1]:[W13]]) -> 0
A19: T-106 | B19: =_xlfn.XLOOKUP('input forecasts'!$A19,'dim tasks'!$A:$A,'dim tasks'!$B:$B,"") -> Front-end development | C19: =_xlfn.XLOOKUP($E19,'dim employees'!$C:$C,'dim employees'!$A:$A,"") -> Senior Engineer | D19: =_xlfn.XLOOKUP($E19,'dim employees'!$C:$C,'dim employees'!$B:$B,"") -> 5 | E19: Noah Turner | F19: =IFERROR(_xlfn.MAXIFS('dim rates'!$D:$D,'dim rates'!$B:$B,'input forecasts'!$D19,'dim rates'!$A:$A,F$3),"") -> 63 | G19: =IFERROR(_xlfn.MAXIFS('dim rates'!$D:$D,'dim rates'!$B:$B,'input forecasts'!$D19,'dim rates'!$A:$A,G$3),"") -> 56.7 | H19: =SUMIFS(actuals!$G:$G,actuals!$A:$A,$A19,actuals!$D:$D,$D19) -> 26 | I19: =SUMIFS(actuals!$J:$J,actuals!$A:$A,$A19,actuals!$D:$D,$D19) -> 1638 | J19: =SUMIFS(actuals!$K:$K,actuals!$A:$A,$A19,actuals!$D:$D,$D19) -> 1474.2 | K19: =Input_Forecast[[#This Row],[Bill Rate/Hour]]*Input_Forecast[[#This Row],[Forecast Hours]] -> 1890 | L19: =Input_Forecast[[#This Row],[FBLR/Hour]]*Input_Forecast[[#This Row],[Forecast Hours]] -> 1701 | M19: =SUM(Input_Forecast[[#This Row],[W1]:[W13]]) -> 30 | S19: 10 | T19: 10 | U19: 10
A20: T-106 | B20: =_xlfn.XLOOKUP('input forecasts'!$A20,'dim tasks'!$A:$A,'dim tasks'!$B:$B,"") -> Front-end development | C20: =_xlfn.XLOOKUP($E20,'dim employees'!$C:$C,'dim employees'!$A:$A,"") -> Apprentice | D20: =_xlfn.XLOOKUP($E20,'dim employees'!$C:$C,'dim employees'!$B:$B,"") -> 9 | E20: Lucas Parker | F20: =IFERROR(_xlfn.MAXIFS('dim rates'!$D:$D,'dim rates'!$B:$B,'input forecasts'!$D20,'dim rates'!$A:$A,F$3),"") -> 21 | G20: =IFERROR(_xlfn.MAXIFS('dim rates'!$D:$D,'dim rates'!$B:$B,'input forecasts'!$D20,'dim rates'!$A:$A,G$3),"") -> 18.9 | H20: =SUMIFS(actuals!$G:$G,actuals!$A:$A,$A20,actuals!$D:$D,$D20) -> 68 | I20: =SUMIFS(actuals!$J:$J,actuals!$A:$A,$A20,actuals!$D:$D,$D20) -> 1428 | J20: =SUMIFS(actuals!$K:$K,actuals!$A:$A,$A20,actuals!$D:$D,$D20) -> 1285.2 | K20: =Input_Forecast[[#This Row],[Bill Rate/Hour]]*Input_Forecast[[#This Row],[Forecast Hours]] -> 2520 | L20: =Input_Forecast[[#This Row],[FBLR/Hour]]*Input_Forecast[[#This Row],[Forecast Hours]] -> 2268 | M20: =SUM(Input_Forecast[[#This Row],[W1]:[W13]]) -> 120 | S20: 40 | T20: 40 | U20: 40
B21: =_xlfn.XLOOKUP('input forecasts'!$A21,'dim tasks'!$A:$A,'dim tasks'!$B:$B,"") -> 0 | C21: =_xlfn.XLOOKUP($E21,'dim employees'!$C:$C,'dim employees'!$A:$A,"") -> 0 | D21: =_xlfn.XLOOKUP($E21,'dim employees'!$C:$C,'dim employees'!$B:$B,"") -> 0 | F21: =IFERROR(_xlfn.MAXIFS('dim rates'!$D:$D,'dim rates'!$B:$B,'input forecasts'!$D21,'dim rates'!$A:$A,F$3),"") -> 0 | G21: =IFERROR(_xlfn.MAXIFS('dim rates'!$D:$D,'dim rates'!$B:$B,'input forecasts'!$D21,'dim rates'!$A:$A,G$3),"") -> 0 | H21: =SUMIFS(actuals!$G:$G,actuals!$A:$A,$A21,actuals!$D:$D,$D21) -> 0 | I21: =SUMIFS(actuals!$J:$J,actuals!$A:$A,$A21,actuals!$D:$D,$D21) -> 0 | J21: =SUMIFS(actuals!$K:$K,actuals!$A:$A,$A21,actuals!$D:$D,$D21) -> 0 | K21: =Input_Forecast[[#This Row],[Bill Rate/Hour]]*Input_Forecast[[#This Row],[Forecast Hours]] -> 0 | L21: =Input_Forecast[[#This Row],[FBLR/Hour]]*Input_Forecast[[#This Row],[Forecast Hours]] -> 0 | M21: =SUM(Input_Forecast[[#This Row],[W1]:[W13]]) -> 0
A22: T-107 | B22: =_xlfn.XLOOKUP('input forecasts'!$A22,'dim tasks'!$A:$A,'dim tasks'!$B:$B,"") -> Back-end development | C22: =_xlfn.XLOOKUP($E22,'dim employees'!$C:$C,'dim employees'!$A:$A,"") -> Senior Engineer | D22: =_xlfn.XLOOKUP($E22,'dim employees'!$C:$C,'dim employees'!$B:$B,"") -> 6 | E22: Amelia Brooks | F22: =IFERROR(_xlfn.MAXIFS('dim rates'!$D:$D,'dim rates'!$B:$B,'input forecasts'!$D22,'dim rates'!$A:$A,F$3),"") -> 63 | G22: =IFERROR(_xlfn.MAXIFS('dim rates'!$D:$D,'dim rates'!$B:$B,'input forecasts'!$D22,'dim rates'!$A:$A,G$3),"") -> 56.7 | H22: =SUMIFS(actuals!$G:$G,actuals!$A:$A,$A22,actuals!$D:$D,$D22) -> 23 | I22: =SUMIFS(actuals!$J:$J,actuals!$A:$A,$A22,actuals!$D:$D,$D22) -> 1449 | J22: =SUMIFS(actuals!$K:$K,actuals!$A:$A,$A22,actuals!$D:$D,$D22) -> 1304.1 | K22: =Input_Forecast[[#This Row],[Bill Rate/Hour]]*Input_Forecast[[#This Row],[Forecast Hours]] -> 1890 | L22: =Input_Forecast[[#This Row],[FBLR/Hour]]*Input_Forecast[[#This Row],[Forecast Hours]] -> 1701 | M22: =SUM(Input_Forecast[[#This Row],[W1]:[W13]]) -> 30 | S22: 10 | T22: 10 | U22: 10
A23: T-107 | B23: =_xlfn.XLOOKUP('input forecasts'!$A23,'dim tasks'!$A:$A,'dim tasks'!$B:$B,"") -> Back-end development | C23: =_xlfn.XLOOKUP($E23,'dim employees'!$C:$C,'dim employees'!$A:$A,"") -> Engineer | D23: =_xlfn.XLOOKUP($E23,'dim employees'!$C:$C,'dim employees'!$B:$B,"") -> 7 | E23: Mason Reed | F23: =IFERROR(_xlfn.MAXIFS('dim rates'!$D:$D,'dim rates'!$B:$B,'input forecasts'!$D23,'dim rates'!$A:$A,F$3),"") -> 42 | G23: =IFERROR(_xlfn.MAXIFS('dim rates'!$D:$D,'dim rates'!$B:$B,'input forecasts'!$D23,'dim rates'!$A:$A,G$3),"") -> 37.8 | H23: =SUMIFS(actuals!$G:$G,actuals!$A:$A,$A23,actuals!$D:$D,$D23) -> 72 | I23: =SUMIFS(actuals!$J:$J,actuals!$A:$A,$A23,actuals!$D:$D,$D23) -> 3024 | J23: =SUMIFS(actuals!$K:$K,actuals!$A:$A,$A23,actuals!$D:$D,$D23) -> 2721.6 | K23: =Input_Forecast[[#This Row],[Bill Rate/Hour]]*Input_Forecast[[#This Row],[Forecast Hours]] -> 5040 | L23: =Input_Forecast[[#This Row],[FBLR/Hour]]*Input_Forecast[[#This Row],[Forecast Hours]] -> 4536 | M23: =SUM(Input_Forecast[[#This Row],[W1]:[W13]]) -> 120 | S23: 40 | T23: 40 | U23: 40
B24: =_xlfn.XLOOKUP('input forecasts'!$A24,'dim tasks'!$A:$A,'dim tasks'!$B:$B,"") -> 0 | C24: =_xlfn.XLOOKUP($E24,'dim employees'!$C:$C,'dim employees'!$A:$A,"") -> 0 | D24: =_xlfn.XLOOKUP($E24,'dim employees'!$C:$C,'dim employees'!$B:$B,"") -> 0 | F24: =IFERROR(_xlfn.MAXIFS('dim rates'!$D:$D,'dim rates'!$B:$B,'input forecasts'!$D24,'dim rates'!$A:$A,F$3),"") -> 0 | G24: =IFERROR(_xlfn.MAXIFS('dim rates'!$D:$D,'dim rates'!$B:$B,'input forecasts'!$D24,'dim rates'!$A:$A,G$3),"") -> 0 | H24: =SUMIFS(actuals!$G:$G,actuals!$A:$A,$A24,actuals!$D:$D,$D24) -> 0 | I24: =SUMIFS(actuals!$J:$J,actuals!$A:$A,$A24,actuals!$D:$D,$D24) -> 0 | J24: =SUMIFS(actuals!$K:$K,actuals!$A:$A,$A24,actuals!$D:$D,$D24) -> 0 | K24: =Input_Forecast[[#This Row],[Bill Rate/Hour]]*Input_Forecast[[#This Row],[Forecast Hours]] -> 0 | L24: =Input_Forecast[[#This Row],[FBLR/Hour]]*Input_Forecast[[#This Row],[Forecast Hours]] -> 0 | M24: =SUM(Input_Forecast[[#This Row],[W1]:[W13]]) -> 0
A25: T-108 | B25: =_xlfn.XLOOKUP('input forecasts'!$A25,'dim tasks'!$A:$A,'dim tasks'!$B:$B,"") -> Unit testing | C25: =_xlfn.XLOOKUP($E25,'dim employees'!$C:$C,'dim employees'!$A:$A,"") -> Senior Engineer | D25: =_xlfn.XLOOKUP($E25,'dim employees'!$C:$C,'dim employees'!$B:$B,"") -> 6 | E25: Amelia Brooks | F25: =IFERROR(_xlfn.MAXIFS('dim rates'!$D:$D,'dim rates'!$B:$B,'input forecasts'!$D25,'dim rates'!$A:$A,F$3),"") -> 63 | G25: =IFERROR(_xlfn.MAXIFS('dim rates'!$D:$D,'dim rates'!$B:$B,'input forecasts'!$D25,'dim rates'!$A:$A,G$3),"") -> 56.7 | H25: =SUMIFS(actuals!$G:$G,actuals!$A:$A,$A25,actuals!$D:$D,$D25) -> 0 | I25: =SUMIFS(actuals!$J:$J,actuals!$A:$A,$A25,actuals!$D:$D,$D25) -> 0 | J25: =SUMIFS(actuals!$K:$K,actuals!$A:$A,$A25,actuals!$D:$D,$D25) -> 0 | K25: =Input_Forecast[[#This Row],[Bill Rate/Hour]]*Input_Forecast[[#This Row],[Forecast Hours]] -> 1260 | L25: =Input_Forecast[[#This Row],[FBLR/Hour]]*Input_Forecast[[#This Row],[Forecast Hours]] -> 1134 | M25: =SUM(Input_Forecast[[#This Row],[W1]:[W13]]) -> 20 | V25: 10 | W25: 10
A26: T-108 | B26: =_xlfn.XLOOKUP('input forecasts'!$A26,'dim tasks'!$A:$A,'dim tasks'!$B:$B,"") -> Unit testing | C26: =_xlfn.XLOOKUP($E26,'dim employees'!$C:$C,'dim employees'!$A:$A,"") -> Apprentice | D26: =_xlfn.XLOOKUP($E26,'dim employees'!$C:$C,'dim employees'!$B:$B,"") -> 9 | E26: Lucas Parker | F26: =IFERROR(_xlfn.MAXIFS('dim rates'!$D:$D,'dim rates'!$B:$B,'input forecasts'!$D26,'dim rates'!$A:$A,F$3),"") -> 21 | G26: =IFERROR(_xlfn.MAXIFS('dim rates'!$D:$D,'dim rates'!$B:$B,'input forecasts'!$D26,'dim rates'!$A:$A,G$3),"") -> 18.9 | H26: =SUMIFS(actuals!$G:$G,actuals!$A:$A,$A26,actuals!$D:$D,$D26) -> 0 | I26: =SUMIFS(actuals!$J:$J,actuals!$A:$A,$A26,actuals!$D:$D,$D26) -> 0 | J26: =SUMIFS(actuals!$K:$K,actuals!$A:$A,$A26,actuals!$D:$D,$D26) -> 0 | K26: =Input_Forecast[[#This Row],[Bill Rate/Hour]]*Input_Forecast[[#This Row],[Forecast Hours]] -> 1680 | L26: =Input_Forecast[[#This Row],[FBLR/Hour]]*Input_Forecast[[#This Row],[Forecast Hours]] -> 1512 | M26: =SUM(Input_Forecast[[#This Row],[W1]:[W13]]) -> 80 | V26: 40 | W26: 40
B27: =_xlfn.XLOOKUP('input forecasts'!$A27,'dim tasks'!$A:$A,'dim tasks'!$B:$B,"") -> 0 | C27: =_xlfn.XLOOKUP($E27,'dim employees'!$C:$C,'dim employees'!$A:$A,"") -> 0 | D27: =_xlfn.XLOOKUP($E27,'dim employees'!$C:$C,'dim employees'!$B:$B,"") -> 0 | F27: =IFERROR(_xlfn.MAXIFS('dim rates'!$D:$D,'dim rates'!$B:$B,'input forecasts'!$D27,'dim rates'!$A:$A,F$3),"") -> 0 | G27: =IFERROR(_xlfn.MAXIFS('dim rates'!$D:$D,'dim rates'!$B:$B,'input forecasts'!$D27,'dim rates'!$A:$A,G$3),"") -> 0 | H27: =SUMIFS(actuals!$G:$G,actuals!$A:$A,$A27,actuals!$D:$D,$D27) -> 0 | I27: =SUMIFS(actuals!$J:$J,actuals!$A:$A,$A27,actuals!$D:$D,$D27) -> 0 | J27: =SUMIFS(actuals!$K:$K,actuals!$A:$A,$A27,actuals!$D:$D,$D27) -> 0 | K27: =Input_Forecast[[#This Row],[Bill Rate/Hour]]*Input_Forecast[[#This Row],[Forecast Hours]] -> 0 | L27: =Input_Forecast[[#This Row],[FBLR/Hour]]*Input_Forecast[[#This Row],[Forecast Hours]] -> 0 | M27: =SUM(Input_Forecast[[#This Row],[W1]:[W13]]) -> 0
A28: T-109 | B28: =_xlfn.XLOOKUP('input forecasts'!$A28,'dim tasks'!$A:$A,'dim tasks'!$B:$B,"") -> Integration testing | C28: =_xlfn.XLOOKUP($E28,'dim employees'!$C:$C,'dim employees'!$A:$A,"") -> Senior Engineer | D28: =_xlfn.XLOOKUP($E28,'dim employees'!$C:$C,'dim employees'!$B:$B,"") -> 5 | E28: Noah Turner | F28: =IFERROR(_xlfn.MAXIFS('dim rates'!$D:$D,'dim rates'!$B:$B,'input forecasts'!$D28,'dim rates'!$A:$A,F$3),"") -> 63 | G28: =IFERROR(_xlfn.MAXIFS('dim rates'!$D:$D,'dim rates'!$B:$B,'input forecasts'!$D28,'dim rates'!$A:$A,G$3),"") -> 56.7 | H28: =SUMIFS(actuals!$G:$G,actuals!$A:$A,$A28,actuals!$D:$D,$D28) -> 0 | I28: =SUMIFS(actuals!$J:$J,actuals!$A:$A,$A28,actuals!$D:$D,$D28) -> 0 | J28: =SUMIFS(actuals!$K:$K,actuals!$A:$A,$A28,actuals!$D:$D,$D28) -> 0 | K28: =Input_Forecast[[#This Row],[Bill Rate/Hour]]*Input_Forecast[[#This Row],[Forecast Hours]] -> 1260 | L28: =Input_Forecast[[#This Row],[FBLR/Hour]]*Input_Forecast[[#This Row],[Forecast Hours]] -> 1134 | M28: =SUM(Input_Forecast[[#This Row],[W1]:[W13]]) -> 20 | V28: 10 | W28: 10
A29: T-109 | B29: =_xlfn.XLOOKUP('input forecasts'!$A29,'dim tasks'!$A:$A,'dim tasks'!$B:$B,"") -> Integration testing | C29: =_xlfn.XLOOKUP($E29,'dim employees'!$C:$C,'dim employees'!$A:$A,"") -> Apprentice | D29: =_xlfn.XLOOKUP($E29,'dim employees'!$C:$C,'dim employees'!$B:$B,"") -> 10 | E29: Grace Sullivan | F29: =IFERROR(_xlfn.MAXIFS('dim rates'!$D:$D,'dim rates'!$B:$B,'input forecasts'!$D29,'dim rates'!$A:$A,F$3),"") -> 21 | G29: =IFERROR(_xlfn.MAXIFS('dim rates'!$D:$D,'dim rates'!$B:$B,'input forecasts'!$D29,'dim rates'!$A:$A,G$3),"") -> 18.9 | H29: =SUMIFS(actuals!$G:$G,actuals!$A:$A,$A29,actuals!$D:$D,$D29) -> 0 | I29: =SUMIFS(actuals!$J:$J,actuals!$A:$A,$A29,actuals!$D:$D,$D29) -> 0 | J29: =SUMIFS(actuals!$K:$K,actuals!$A:$A,$A29,actuals!$D:$D,$D29) -> 0 | K29: =Input_Forecast[[#This Row],[Bill Rate/Hour]]*Input_Forecast[[#This Row],[Forecast Hours]] -> 1680 | L29: =Input_Forecast[[#This Row],[FBLR/Hour]]*Input_Forecast[[#This Row],[Forecast Hours]] -> 1512 | M29: =SUM(Input_Forecast[[#This Row],[W1]:[W13]]) -> 80 | V29: 40 | W29: 40
B30: =_xlfn.XLOOKUP('input forecasts'!$A30,'dim tasks'!$A:$A,'dim tasks'!$B:$B,"") -> 0 | C30: =_xlfn.XLOOKUP($E30,'dim employees'!$C:$C,'dim employees'!$A:$A,"") -> 0 | D30: =_xlfn.XLOOKUP($E30,'dim employees'!$C:$C,'dim employees'!$B:$B,"") -> 0 | F30: =IFERROR(_xlfn.MAXIFS('dim rates'!$D:$D,'dim rates'!$B:$B,'input forecasts'!$D30,'dim rates'!$A:$A,F$3),"") -> 0 | G30: =IFERROR(_xlfn.MAXIFS('dim rates'!$D:$D,'dim rates'!$B:$B,'input forecasts'!$D30,'dim rates'!$A:$A,G$3),"") -> 0 | H30: =SUMIFS(actuals!$G:$G,actuals!$A:$A,$A30,actuals!$D:$D,$D30) -> 0 | I30: =SUMIFS(actuals!$J:$J,actuals!$A:$A,$A30,actuals!$D:$D,$D30) -> 0 | J30: =SUMIFS(actuals!$K:$K,actuals!$A:$A,$A30,actuals!$D:$D,$D30) -> 0 | K30: =Input_Forecast[[#This Row],[Bill Rate/Hour]]*Input_Forecast[[#This Row],[Forecast Hours]] -> 0 | L30: =Input_Forecast[[#This Row],[FBLR/Hour]]*Input_Forecast[[#This Row],[Forecast Hours]] -> 0 | M30: =SUM(Input_Forecast[[#This Row],[W1]:[W13]]) -> 0
A31: T-110 | B31: =_xlfn.XLOOKUP('input forecasts'!$A31,'dim tasks'!$A:$A,'dim tasks'!$B:$B,"") -> User acceptance testing | C31: =_xlfn.XLOOKUP($E31,'dim employees'!$C:$C,'dim employees'!$A:$A,"") -> Manager | D31: =_xlfn.XLOOKUP($E31,'dim employees'!$C:$C,'dim employees'!$B:$B,"") -> 3 | E31: Liam Foster | F31: =IFERROR(_xlfn.MAXIFS('dim rates'!$D:$D,'dim rates'!$B:$B,'input forecasts'!$D31,'dim rates'!$A:$A,F$3),"") -> 84 | G31: =IFERROR(_xlfn.MAXIFS('dim rates'!$D:$D,'dim rates'!$B:$B,'input forecasts'!$D31,'dim rates'!$A:$A,G$3),"") -> 75.6 | H31: =SUMIFS(actuals!$G:$G,actuals!$A:$A,$A31,actuals!$D:$D,$D31) -> 0 | I31: =SUMIFS(actuals!$J:$J,actuals!$A:$A,$A31,actuals!$D:$D,$D31) -> 0 | J31: =SUMIFS(actuals!$K:$K,actuals!$A:$A,$A31,actuals!$D:$D,$D31) -> 0 | K31: =Input_Forecast[[#This Row],[Bill Rate/Hour]]*Input_Forecast[[#This Row],[Forecast Hours]] -> 1680 | L31: =Input_Forecast[[#This Row],[FBLR/Hour]]*Input_Forecast[[#This Row],[Forecast Hours]] -> 1512 | M31: =SUM(Input_Forecast[[#This Row],[W1]:[W13]]) -> 20 | V31: 10 | W31: 10
A32: T-110 | B32: =_xlfn.XLOOKUP('input forecasts'!$A32,'dim tasks'!$A:$A,'dim tasks'!$B:$B,"") -> User acceptance testing | C32: =_xlfn.XLOOKUP($E32,'dim employees'!$C:$C,'dim employees'!$A:$A,"") -> Apprentice | D32: =_xlfn.XLOOKUP($E32,'dim employees'!$C:$C,'dim employees'!$B:$B,"") -> 9 | E32: Lucas Parker | F32: =IFERROR(_xlfn.MAXIFS('dim rates'!$D:$D,'dim rates'!$B:$B,'input forecasts'!$D32,'dim rates'!$A:$A,F$3),"") -> 21 | G32: =IFERROR(_xlfn.MAXIFS('dim rates'!$D:$D,'dim rates'!$B:$B,'input forecasts'!$D32,'dim rates'!$A:$A,G$3),"") -> 18.9 | H32: =SUMIFS(actuals!$G:$G,actuals!$A:$A,$A32,actuals!$D:$D,$D32) -> 0 | I32: =SUMIFS(actuals!$J:$J,actuals!$A:$A,$A32,actuals!$D:$D,$D32) -> 0 | J32: =SUMIFS(actuals!$K:$K,actuals!$A:$A,$A32,actuals!$D:$D,$D32) -> 0 | K32: =Input_Forecast[[#This Row],[Bill Rate/Hour]]*Input_Forecast[[#This Row],[Forecast Hours]] -> 1680 | L32: =Input_Forecast[[#This Row],[FBLR/Hour]]*Input_Forecast[[#This Row],[Forecast Hours]] -> 1512 | M32: =SUM(Input_Forecast[[#This Row],[W1]:[W13]]) -> 80 | V32: 40 | W32: 40
B33: =_xlfn.XLOOKUP('input forecasts'!$A33,'dim tasks'!$A:$A,'dim tasks'!$B:$B,"") -> 0 | C33: =_xlfn.XLOOKUP($E33,'dim employees'!$C:$C,'dim employees'!$A:$A,"") -> 0 | D33: =_xlfn.XLOOKUP($E33,'dim employees'!$C:$C,'dim employees'!$B:$B,"") -> 0 | F33: =IFERROR(_xlfn.MAXIFS('dim rates'!$D:$D,'dim rates'!$B:$B,'input forecasts'!$D33,'dim rates'!$A:$A,F$3),"") -> 0 | G33: =IFERROR(_xlfn.MAXIFS('dim rates'!$D:$D,'dim rates'!$B:$B,'input forecasts'!$D33,'dim rates'!$A:$A,G$3),"") -> 0 | H33: =SUMIFS(actuals!$G:$G,actuals!$A:$A,$A33,actuals!$D:$D,$D33) -> 0 | I33: =SUMIFS(actuals!$J:$J,actuals!$A:$A,$A33,actuals!$D:$D,$D33) -> 0 | J33: =SUMIFS(actuals!$K:$K,actuals!$A:$A,$A33,actuals!$D:$D,$D33) -> 0 | K33: =Input_Forecast[[#This Row],[Bill Rate/Hour]]*Input_Forecast[[#This Row],[Forecast Hours]] -> 0 | L33: =Input_Forecast[[#This Row],[FBLR/Hour]]*Input_Forecast[[#This Row],[Forecast Hours]] -> 0 | M33: =SUM(Input_Forecast[[#This Row],[W1]:[W13]]) -> 0
A34: T-111 | B34: =_xlfn.XLOOKUP('input forecasts'!$A34,'dim tasks'!$A:$A,'dim tasks'!$B:$B,"") -> Production deployment | C34: =_xlfn.XLOOKUP($E34,'dim employees'!$C:$C,'dim employees'!$A:$A,"") -> Manager | D34: =_xlfn.XLOOKUP($E34,'dim employees'!$C:$C,'dim employees'!$B:$B,"") -> 4 | E34: Sophia Mitchell | F34: =IFERROR(_xlfn.MAXIFS('dim rates'!$D:$D,'dim rates'!$B:$B,'input forecasts'!$D34,'dim rates'!$A:$A,F$3),"") -> 84 | G34: =IFERROR(_xlfn.MAXIFS('dim rates'!$D:$D,'dim rates'!$B:$B,'input forecasts'!$D34,'dim rates'!$A:$A,G$3),"") -> 75.6 | H34: =SUMIFS(actuals!$G:$G,actuals!$A:$A,$A34,actuals!$D:$D,$D34) -> 0 | I34: =SUMIFS(actuals!$J:$J,actuals!$A:$A,$A34,actuals!$D:$D,$D34) -> 0 | J34: =SUMIFS(actuals!$K:$K,actuals!$A:$A,$A34,actuals!$D:$D,$D34) -> 0 | K34: =Input_Forecast[[#This Row],[Bill Rate/Hour]]*Input_Forecast[[#This Row],[Forecast Hours]] -> 3360 | L34: =Input_Forecast[[#This Row],[FBLR/Hour]]*Input_Forecast[[#This Row],[Forecast Hours]] -> 3024 | M34: =SUM(Input_Forecast[[#This Row],[W1]:[W13]]) -> 40 | X34: 20 | Y34: 20
A35: T-111 | B35: =_xlfn.XLOOKUP('input forecasts'!$A35,'dim tasks'!$A:$A,'dim tasks'!$B:$B,"") -> Production deployment | C35: =_xlfn.XLOOKUP($E35,'dim employees'!$C:$C,'dim employees'!$A:$A,"") -> Senior Engineer | D35: =_xlfn.XLOOKUP($E35,'dim employees'!$C:$C,'dim employees'!$B:$B,"") -> 5 | E35: Noah Turner | F35: =IFERROR(_xlfn.MAXIFS('dim rates'!$D:$D,'dim rates'!$B:$B,'input forecasts'!$D35,'dim rates'!$A:$A,F$3),"") -> 63 | G35: =IFERROR(_xlfn.MAXIFS('dim rates'!$D:$D,'dim rates'!$B:$B,'input forecasts'!$D35,'dim rates'!$A:$A,G$3),"") -> 56.7 | H35: =SUMIFS(actuals!$G:$G,actuals!$A:$A,$A35,actuals!$D:$D,$D35) -> 0 | I35: =SUMIFS(actuals!$J:$J,actuals!$A:$A,$A35,actuals!$D:$D,$D35) -> 0 | J35: =SUMIFS(actuals!$K:$K,actuals!$A:$A,$A35,actuals!$D:$D,$D35) -> 0 | K35: =Input_Forecast[[#This Row],[Bill Rate/Hour]]*Input_Forecast[[#This Row],[Forecast Hours]] -> 3780 | L35: =Input_Forecast[[#This Row],[FBLR/Hour]]*Input_Forecast[[#This Row],[Forecast Hours]] -> 3402 | M35: =SUM(Input_Forecast[[#This Row],[W1]:[W13]]) -> 60 | X35: 30 | Y35: 30
B36: =_xlfn.XLOOKUP('input forecasts'!$A36,'dim tasks'!$A:$A,'dim tasks'!$B:$B,"") -> 0 | C36: =_xlfn.XLOOKUP($E36,'dim employees'!$C:$C,'dim employees'!$A:$A,"") -> 0 | D36: =_xlfn.XLOOKUP($E36,'dim employees'!$C:$C,'dim employees'!$B:$B,"") -> 0 | F36: =IFERROR(_xlfn.MAXIFS('dim rates'!$D:$D,'dim rates'!$B:$B,'input forecasts'!$D36,'dim rates'!$A:$A,F$3),"") -> 0 | G36: =IFERROR(_xlfn.MAXIFS('dim rates'!$D:$D,'dim rates'!$B:$B,'input forecasts'!$D36,'dim rates'!$A:$A,G$3),"") -> 0 | H36: =SUMIFS(actuals!$G:$G,actuals!$A:$A,$A36,actuals!$D:$D,$D36) -> 0 | I36: =SUMIFS(actuals!$J:$J,actuals!$A:$A,$A36,actuals!$D:$D,$D36) -> 0 | J36: =SUMIFS(actuals!$K:$K,actuals!$A:$A,$A36,actuals!$D:$D,$D36) -> 0 | K36: =Input_Forecast[[#This Row],[Bill Rate/Hour]]*Input_Forecast[[#This Row],[Forecast Hours]] -> 0 | L36: =Input_Forecast[[#This Row],[FBLR/Hour]]*Input_Forecast[[#This Row],[Forecast Hours]] -> 0 | M36: =SUM(Input_Forecast[[#This Row],[W1]:[W13]]) -> 0
A37: T-112 | B37: =_xlfn.XLOOKUP('input forecasts'!$A37,'dim tasks'!$A:$A,'dim tasks'!$B:$B,"") -> Project closure | C37: =_xlfn.XLOOKUP($E37,'dim employees'!$C:$C,'dim employees'!$A:$A,"") -> Director | D37: =_xlfn.XLOOKUP($E37,'dim employees'!$C:$C,'dim employees'!$B:$B,"") -> 2 | E37: Olivia Bennett | F37: =IFERROR(_xlfn.MAXIFS('dim rates'!$D:$D,'dim rates'!$B:$B,'input forecasts'!$D37,'dim rates'!$A:$A,F$3),"") -> 105 | G37: =IFERROR(_xlfn.MAXIFS('dim rates'!$D:$D,'dim rates'!$B:$B,'input forecasts'!$D37,'dim rates'!$A:$A,G$3),"") -> 94.5 | H37: =SUMIFS(actuals!$G:$G,actuals!$A:$A,$A37,actuals!$D:$D,$D37) -> 0 | I37: =SUMIFS(actuals!$J:$J,actuals!$A:$A,$A37,actuals!$D:$D,$D37) -> 0 | J37: =SUMIFS(actuals!$K:$K,actuals!$A:$A,$A37,actuals!$D:$D,$D37) -> 0 | K37: =Input_Forecast[[#This Row],[Bill Rate/Hour]]*Input_Forecast[[#This Row],[Forecast Hours]] -> 525 | L37: =Input_Forecast[[#This Row],[FBLR/Hour]]*Input_Forecast[[#This Row],[Forecast Hours]] -> 472.5 | M37: =SUM(Input_Forecast[[#This Row],[W1]:[W13]]) -> 5 | Z37: 5
A38: T-112 | B38: =_xlfn.XLOOKUP('input forecasts'!$A38,'dim tasks'!$A:$A,'dim tasks'!$B:$B,"") -> Project closure | C38: =_xlfn.XLOOKUP($E38,'dim employees'!$C:$C,'dim employees'!$A:$A,"") -> Manager | D38: =_xlfn.XLOOKUP($E38,'dim employees'!$C:$C,'dim employees'!$B:$B,"") -> 4 | E38: Sophia Mitchell | F38: =IFERROR(_xlfn.MAXIFS('dim rates'!$D:$D,'dim rates'!$B:$B,'input forecasts'!$D38,'dim rates'!$A:$A,F$3),"") -> 84 | G38: =IFERROR(_xlfn.MAXIFS('dim rates'!$D:$D,'dim rates'!$B:$B,'input forecasts'!$D38,'dim rates'!$A:$A,G$3),"") -> 75.6 | H38: =SUMIFS(actuals!$G:$G,actuals!$A:$A,$A38,actuals!$D:$D,$D38) -> 0 | I38: =SUMIFS(actuals!$J:$J,actuals!$A:$A,$A38,actuals!$D:$D,$D38) -> 0 | J38: =SUMIFS(actuals!$K:$K,actuals!$A:$A,$A38,actuals!$D:$D,$D38) -> 0 | K38: =Input_Forecast[[#This Row],[Bill Rate/Hour]]*Input_Forecast[[#This Row],[Forecast Hours]] -> 840 | L38: =Input_Forecast[[#This Row],[FBLR/Hour]]*Input_Forecast[[#This Row],[Forecast Hours]] -> 756 | M38: =SUM(Input_Forecast[[#This Row],[W1]:[W13]]) -> 10 | Z38: 10
B39: =_xlfn.XLOOKUP('input forecasts'!$A39,'dim tasks'!$A:$A,'dim tasks'!$B:$B,"") -> 0 | C39: =_xlfn.XLOOKUP($E39,'dim employees'!$C:$C,'dim employees'!$A:$A,"") -> 0 | D39: =_xlfn.XLOOKUP($E39,'dim employees'!$C:$C,'dim employees'!$B:$B,"") -> 0 | F39: =IFERROR(_xlfn.MAXIFS('dim rates'!$D:$D,'dim rates'!$B:$B,'input forecasts'!$D39,'dim rates'!$A:$A,F$3),"") -> 0 | G39: =IFERROR(_xlfn.MAXIFS('dim rates'!$D:$D,'dim rates'!$B:$B,'input forecasts'!$D39,'dim rates'!$A:$A,G$3),"") -> 0 | H39: =SUMIFS(actuals!$G:$G,actuals!$A:$A,$A39,actuals!$D:$D,$D39) -> 0 | I39: =SUMIFS(actuals!$J:$J,actuals!$A:$A,$A39,actuals!$D:$D,$D39) -> 0 | J39: =SUMIFS(actuals!$K:$K,actuals!$A:$A,$A39,actuals!$D:$D,$D39) -> 0 | K39: =Input_Forecast[[#This Row],[Bill Rate/Hour]]*Input_Forecast[[#This Row],[Forecast Hours]] -> 0 | L39: =Input_Forecast[[#This Row],[FBLR/Hour]]*Input_Forecast[[#This Row],[Forecast Hours]] -> 0 | M39: =SUM(Input_Forecast[[#This Row],[W1]:[W13]]) -> 0

Sheet fact forecasts
A1: fact forecasts
A2: Task Code | B2: Task Name | C2: Employee Title | D2: Employee Number | E2: Employee Name | F2: Week Number | G2: Week Ending | H2: Financial Year | I2: Hours | J2: Bill Rate/Hour | K2: FLBR Rate/Hour | L2: Forecast Bill | M2: Forecast FBLR
A3: T-101 | B3: Requirements gathering | C3: Director | D3: 1 | E3: Ethan Carter | F3: W1 | G3: 46207 | H3: FY26 | I3: 5 | J3: 100 | K3: 90 | L3: 500 | M3: 450
A4: T-101 | B4: Requirements gathering | C4: Director | D4: 1 | E4: Ethan Carter | F4: W2 | G4: 46214 | H4: FY26 | I4: 5 | J4: 100 | K4: 90 | L4: 500 | M4: 450
A5: T-102 | B5: Scope definition | C5: Director | D5: 1 | E5: Ethan Carter | F5: W2 | G5: 46214 | H5: FY26 | I5: 5 | J5: 100 | K5: 90 | L5: 500 | M5: 450
A6: T-102 | B6: Scope definition | C6: Director | D6: 1 | E6: Ethan Carter | F6: W3 | G6: 46221 | H6: FY26 | I6: 5 | J6: 100 | K6: 90 | L6: 500 | M6: 450
A7: T-101 | B7: Requirements gathering | C7: Director | D7: 2 | E7: Olivia Bennett | F7: W1 | G7: 46207 | H7: FY26 | I7: 10 | J7: 100 | K7: 90 | L7: 1000 | M7: 900
A8: T-101 | B8: Requirements gathering | C8: Director | D8: 2 | E8: Olivia Bennett | F8: W2 | G8: 46214 | H8: FY26 | I8: 10 | J8: 100 | K8: 90 | L8: 1000 | M8: 900
A9: T-103 | B9: Project planning | C9: Director | D9: 2 | E9: Olivia Bennett | F9: W2 | G9: 46214 | H9: FY26 | I9: 10 | J9: 100 | K9: 90 | L9: 1000 | M9: 900
A10: T-103 | B10: Project planning | C10: Director | D10: 2 | E10: Olivia Bennett | F10: W3 | G10: 46221 | H10: FY26 | I10: 10 | J10: 100 | K10: 90 | L10: 1000 | M10: 900
A11: T-103 | B11: Project planning | C11: Manager | D11: 3 | E11: Liam Foster | F11: W2 | G11: 46214 | H11: FY26 | I11: 20 | J11: 80 | K11: 72 | L11: 1600 | M11: 1440
A12: T-103 | B12: Project planning | C12: Manager | D12: 3 | E12: Liam Foster | F12: W3 | G12: 46221 | H12: FY26 | I12: 20 | J12: 80 | K12: 72 | L12: 1600 | M12: 1440
A13: T-105 | B13: Database design | C13: Manager | D13: 3 | E13: Liam Foster | F13: W4 | G13: 46228 | H13: FY26 | I13: 10 | J13: 80 | K13: 72 | L13: 800 | M13: 720
A14: T-105 | B14: Database design | C14: Manager | D14: 3 | E14: Liam Foster | F14: W5 | G14: 46235 | H14: FY27 | I14: 10 | J14: 84 | K14: 75.6 | L14: 840 | M14: 756
... A52: T-112 | B52: Project closure | C52: Manager | D52: 4 | E52: Sophia Mitchell | F52: W13 | G52: 46291 | H52: FY27 | I52: 10 | J52: 84 | K52: 75.6 | L52: 840 | M52: 756

Sheet input rates
A1: input rates
A2: Rate Type | B2: Employee Number | C2: FY26 | D2: FY27 | G2: Rate Type | H2: Employee Number | I2: FY26 | J2: FY27 | M2: Rate Type | N2: Employee Number | O2: FY26 | P2: FY27
A3: Bill Rate/Hour | B3: 1 | C3: 100 | D3: =C3*(1.05) -> 105 | G3: FBLR/Hour | H3: 1 | I3: =C3*0.9 -> 90 | J3: =I3*(1.05) -> 94.5 | M3: Raw Rate/Hour | N3: 1 | O3: =I3/2 -> 45 | P3: =O3*(1.05) -> 47.25
A4: Bill Rate/Hour | B4: 2 | C4: 100 | D4: =C4*(1.05) -> 105 | G4: FBLR/Hour | H4: 2 | I4: =C4*0.9 -> 90 | J4: =I4*(1.05) -> 94.5 | M4: Raw Rate/Hour | N4: 2 | O4: =I4/2 -> 45 | P4: =O4*(1.05) -> 47.25
A5: Bill Rate/Hour | B5: 3 | C5: 80 | D5: =C5*(1.05) -> 84 | G5: FBLR/Hour | H5: 3 | I5: =C5*0.9 -> 72 | J5: =I5*(1.05) -> 75.6 | M5: Raw Rate/Hour | N5: 3 | O5: =I5/2 -> 36 | P5: =O5*(1.05) -> 37.8
A6: Bill Rate/Hour | B6: 4 | C6: 80 | D6: =C6*(1.05) -> 84 | G6: FBLR/Hour | H6: 4 | I6: =C6*0.9 -> 72 | J6: =I6*(1.05) -> 75.6 | M6: Raw Rate/Hour | N6: 4 | O6: =I6/2 -> 36 | P6: =O6*(1.05) -> 37.8
A7: Bill Rate/Hour | B7: 5 | C7: 60 | D7: =C7*(1.05) -> 63 | G7: FBLR/Hour | H7: 5 | I7: =C7*0.9 -> 54 | J7: =I7*(1.05) -> 56.7 | M7: Raw Rate/Hour | N7: 5 | O7: =I7/2 -> 27 | P7: =O7*(1.05) -> 28.35
A8: Bill Rate/Hour | B8: 6 | C8: 60 | D8: =C8*(1.05) -> 63 | G8: FBLR/Hour | H8: 6 | I8: =C8*0.9 -> 54 | J8: =I8*(1.05) -> 56.7 | M8: Raw Rate/Hour | N8: 6 | O8: =I8/2 -> 27 | P8: =O8*(1.05) -> 28.35
A9: Bill Rate/Hour | B9: 7 | C9: 40 | D9: =C9*(1.05) -> 42 | G9: FBLR/Hour | H9: 7 | I9: =C9*0.9 -> 36 | J9: =I9*(1.05) -> 37.8 | M9: Raw Rate/Hour | N9: 7 | O9: =I9/2 -> 18 | P9: =O9*(1.05) -> 18.9
A10: Bill Rate/Hour | B10: 8 | C10: 40 | D10: =C10*(1.05) -> 42 | G10: FBLR/Hour | H10: 8 | I10: =C10*0.9 -> 36 | J10: =I10*(1.05) -> 37.8 | M10: Raw Rate/Hour | N10: 8 | O10: =I10/2 -> 18 | P10: =O10*(1.05) -> 18.9
A11: Bill Rate/Hour | B11: 9 | C11: 20 | D11: =C11*(1.05) -> 21 | G11: FBLR/Hour | H11: 9 | I11: =C11*0.9 -> 18 | J11: =I11*(1.05) -> 18.9 | M11: Raw Rate/Hour | N11: 9 | O11: =I11/2 -> 9 | P11: =O11*(1.05) -> 9.45
A12: Bill Rate/Hour | B12: 10 | C12: 20 | D12: =C12*(1.05) -> 21 | G12: FBLR/Hour | H12: 10 | I12: =C12*0.9 -> 18 | J12: =I12*(1.05) -> 18.9 | M12: Raw Rate/Hour | N12: 10 | O12: =I12/2 -> 9 | P12: =O12*(1.05) -> 9.45

Sheet dim rates
A1: dim rates
A2: Rate Type | B2: Employee Number | C2: FY | D2: Rate
A3: Bill Rate/Hour | B3: 1 | C3: FY26 | D3: 100
A4: Bill Rate/Hour | B4: 1 | C4: FY27 | D4: 105
A5: Bill Rate/Hour | B5: 2 | C5: FY26 | D5: 100
A6: Bill Rate/Hour | B6: 2 | C6: FY27 | D6: 105
